2019-12-30 23:42:21,306 ERROR: Exception on /reset_password/eyJ0eXAiOiJKV1QiLCJhbGciOiJIUzI1NiJ9.eyJyZXNldF9wYXNzd29yZCI6MSwiZXhwIjoxNTc3NzcyOTQ2LjE5MzY4NDZ9.X9TQB2tsGsoUMVn1mSbkOrE6olMnmNQ3AxNhSI-DDSQ [POST] [in C:\Users\Esther Goldberg\PycharmProjects\Esther Goldberg Final Project\venv\lib\site-packages\flask\app.py:1890]
Traceback (most recent call last):
  File "C:\Users\Esther Goldberg\PycharmProjects\Esther Goldberg Final Project\venv\lib\site-packages\flask\app.py", line 2446, in wsgi_app
    response = self.full_dispatch_request()
  File "C:\Users\Esther Goldberg\PycharmProjects\Esther Goldberg Final Project\venv\lib\site-packages\flask\app.py", line 1951, in full_dispatch_request
    rv = self.handle_user_exception(e)
  File "C:\Users\Esther Goldberg\PycharmProjects\Esther Goldberg Final Project\venv\lib\site-packages\flask\app.py", line 1820, in handle_user_exception
    reraise(exc_type, exc_value, tb)
  File "C:\Users\Esther Goldberg\PycharmProjects\Esther Goldberg Final Project\venv\lib\site-packages\flask\_compat.py", line 39, in reraise
    raise value
  File "C:\Users\Esther Goldberg\PycharmProjects\Esther Goldberg Final Project\venv\lib\site-packages\flask\app.py", line 1949, in full_dispatch_request
    rv = self.dispatch_request()
  File "C:\Users\Esther Goldberg\PycharmProjects\Esther Goldberg Final Project\venv\lib\site-packages\flask\app.py", line 1935, in dispatch_request
    return self.view_functions[rule.endpoint](**req.view_args)
  File "C:\Users\Esther Goldberg\PycharmProjects\Esther Goldberg Final Project\app\routes.py", line 169, in reset_password
    user = User.verify_reset_password_token(token)
  File "C:\Users\Esther Goldberg\PycharmProjects\Esther Goldberg Final Project\app\models.py", line 81, in verify_reset_password_token
    return User.query.get(id)
  File "C:\Users\Esther Goldberg\PycharmProjects\Esther Goldberg Final Project\venv\lib\site-packages\sqlalchemy\orm\query.py", line 982, in get
    return self._get_impl(ident, loading.load_on_pk_identity)
  File "C:\Users\Esther Goldberg\PycharmProjects\Esther Goldberg Final Project\venv\lib\site-packages\sqlalchemy\orm\query.py", line 1052, in _get_impl
    raise sa_exc.InvalidRequestError(
sqlalchemy.exc.InvalidRequestError: Incorrect number of values in identifier to formulate primary key for query.get(); primary key columns are 'user.id'
2019-12-30 23:43:28,671 INFO: Microblog startup [in C:\Users\Esther Goldberg\PycharmProjects\Esther Goldberg Final Project\app\__init__.py:47]
2019-12-30 23:44:36,455 INFO: Microblog startup [in C:\Users\Esther Goldberg\PycharmProjects\Esther Goldberg Final Project\app\__init__.py:47]
2019-12-30 23:49:25,056 INFO: Microblog startup [in C:\Users\Esther Goldberg\PycharmProjects\Esther Goldberg Final Project\app\__init__.py:47]
2019-12-30 23:51:18,010 INFO: Microblog startup [in C:\Users\Esther Goldberg\PycharmProjects\Esther Goldberg Final Project\app\__init__.py:47]
2019-12-30 23:55:08,864 INFO: Microblog startup [in C:\Users\Esther Goldberg\PycharmProjects\Esther Goldberg Final Project\app\__init__.py:47]
2019-12-31 17:54:08,717 INFO: Microblog startup [in C:\Users\Esther Goldberg\PycharmProjects\Esther Goldberg Final Project\app\__init__.py:47]
